Workbook
Name _C45_EXC_M: #REF!
Name _C45_EXC_M: #REF!
Name \0: '[1]PNT-QUOT-#3'!#REF!
Name \0: '[1]PNT-QUOT-#3'!#REF!
Name \z: '[1]COAT&WRAP-QIOT-#3'!#REF!
Name \z: '[1]COAT&WRAP-QIOT-#3'!#REF!
Name a: [2]Code!$E$2:$E$6
Name AAA: '[3]MTL$-INTER'!#REF!
Name AAA: '[3]MTL$-INTER'!#REF!
Name àhkffjfjkhfh: '[1]PNT-QUOT-#3'!#REF!
Name B: '[1]PNT-QUOT-#3'!#REF!
Name B: '[1]PNT-QUOT-#3'!#REF!
Name bangcap: [4]Ma!$A$2:$A$9
Name BarData: #REF!
Name BarData: #REF!
Name bgia: #REF!
Name bgia: #REF!
Name BHS: #REF!
Name BHS: #REF!
Name bt: #REF!
Name bt: #REF!
Name bv: #REF!
Name bv: #REF!
Name chuannangluc: '[5]Chuan NL'!$B$2:$G$237
Name chucdanhchuan: '[6]Danh muc chuc danh'!$E$3:$E$43
Name cnct: #REF!
Name cnct: #REF!
Name COAT: '[1]PNT-QUOT-#3'!#REF!
Name COAT: '[1]PNT-QUOT-#3'!#REF!
Name cot: #REF!
Name cot: #REF!
Name CS_10: #REF!
Name CS_10: #REF!
Name CS_100: #REF!
Name CS_100: #REF!
Name CS_10S: #REF!
Name CS_10S: #REF!
Name CS_120: #REF!
Name CS_120: #REF!
Name CS_140: #REF!
Name CS_140: #REF!
Name CS_160: #REF!
Name CS_160: #REF!
Name CS_20: #REF!
Name CS_20: #REF!
Name CS_30: #REF!
Name CS_30: #REF!
Name CS_40: #REF!
Name CS_40: #REF!
Name CS_40S: #REF!
Name CS_40S: #REF!
Name CS_5S: #REF!
Name CS_5S: #REF!
Name CS_60: #REF!
Name CS_60: #REF!
Name CS_80: #REF!
Name CS_80: #REF!
Name CS_80S: #REF!
Name CS_80S: #REF!
Name CS_STD: #REF!

Sheet Quý 3,2025
C1: CÔNG TY CỔ PHẦN DƯỢC PHẨM ABIPHA
C2: Địa chỉ: Số 5 liền kề 15, khu đô thị Văn phú, P. Phú La, Q. Hà Đông, Hà nội
A3: BẢNG KHOÁN DOANH SỐ QUÝ 3/2025 - ABIPHA MIỀN BẮC
A5: Chỉ tiêu | J5: Tháng 7/2025 | Q5: Tháng 8/2025 | X5: Tháng 9/2025 | AE5: Tổng quý 3/2025
J6: Doanh số | O6: KPI 1 Đông dược + tân dược | P6: KPI 2 hợp đồng mở mới | Q6: Doanh số | V6: KPI 1 Đông dược + tân dược | W6: KPI 2 hợp đồng mở mới | X6: Doanh số | AC6: KPI 1 Đông dược + tân dược | AD6: KPI 2 hợp đồng mở mới | AE6: Doanh số | AJ6: KPI 1 Đông dược + tân dược | AK6: KPI 2 hợp đồng mở mới
J7: Nhóm thuốc tân dược | K7: Nhóm thuốc đông dược | L7: Nhóm TPCN 1 | M7: Nhóm TPCN 2 | N7: Tổng | Q7: Nhóm thuốc tân dược | R7: Nhóm thuốc đông dược | S7: Nhóm TPCN 1 | T7: Nhóm TPCN 2 | U7: Tổng | X7: Nhóm thuốc tân dược | Y7: Nhóm thuốc đông dược | Z7: Nhóm TPCN 1 | AA7: Nhóm TPCN 2 | AB7: Tổng | AE7: Nhóm thuốc tân dược | AF7: Nhóm thuốc đông dược | AG7: Nhóm TPCN 1 | AH7: Nhóm TPCN 2 | AI7: Tổng | AL7: 11033750000
A8: Tổng khoán GĐKD OTC | J8: =N8*J9 -> 350000000 | K8: =N8*K9 -> 1400000000 | L8: =N8*L9 -> 1050000000 | M8: =N8*M9 -> 700000000 | N8: 3500000000 | O8: 12000 | P8: 200 | Q8: =U8*Q9 -> 367500000 | R8: =U8*R9 -> 1470000000 | S8: =U8*S9 -> 1102500000 | T8: =U8*T9 -> 735000000 | U8: =N8*105% -> 3675000000 | V8: =O8+1000 -> 13000 | W8: 180 | X8: =AB8*X9 -> 385875000 | Y8: =AB8*Y9 -> 1543500000 | Z8: =AB8*Z9 -> 1157625000 | AA8: =AB8*AA9 -> 771750000 | AB8: =U8*105% -> 3858750000 | AC8: =V8+1000 -> 14000 | AD8: 150 | AE8: =SUMIF($J$7:$AB$7,AE$12,$J8:$AB8) -> 1103375000 | AF8: =SUMIF($J$7:$AB$7,AF$12,$J8:$AB8) -> 4413500000 | AG8: =SUMIF($J$7:$AB$7,AG$12,$J8:$AB8) -> 3310125000 | AH8: =SUMIF($J$7:$AB$7,AH$12,$J8:$AB8) -> 2206750000 | AI8: =SUM(AE8:AH8) -> 11033750000 | AJ8: =SUMIF($J$6:$AD$6,AJ$6,$J8:$AD8) -> 39000 | AK8: =SUMIF($J$6:$AD$6,AK$6,$J8:$AD8) -> 530 | AL8: =AI8+'[13]Quý 3,2025'!$AI$9 -> 13240500000
I9: 3 | J9: 0.1 | K9: 0.4 | L9: 0.3 | M9: 0.2 | Q9: 0.1 | R9: 0.4 | S9: 0.3 | T9: 0.2 | X9: 0.1 | Y9: 0.4 | Z9: 0.3 | AA9: 0.2 | AE9: 0.1 | AF9: 0.4 | AG9: 0.3 | AH9: 0.2
A10: Stt | B10: Mã | C10: Tên nhân sự | D10: Khu vực | E10: Địa bàn | F10: Doanh số đạt từ tháng 3-5/2025 | J10: Tháng 7/2025 | Q10: Tháng 8/2025 | X10: Tháng 9/2025 | AE10: Tổng quý 3/2025
F11: Tháng 3 | G11: Tháng 4 | H11: Tháng 5 | I11: TB đạt/tháng | J11: Doanh số | O11: KPI 1 Đông dược + tân dược | P11: KPI 2 hợp đồng mở mới | Q11: Doanh số | V11: KPI 1 Đông dược + tân dược | W11: KPI 2 hợp đồng mở mới | X11: Doanh số | AC11: KPI 1 Đông dược + tân dược | AD11: KPI 2 hợp đồng mở mới | AE11: Doanh số | AJ11: KPI 1 Đông dược + tân dược | AK11: KPI 2 hợp đồng mở mới
J12: Nhóm thuốc tân dược | K12: Nhóm thuốc đông dược | L12: Nhóm TPCN 1 | M12: Nhóm TPCN 2 | N12: Tổng | Q12: Nhóm thuốc tân dược | R12: Nhóm thuốc đông dược | S12: Nhóm TPCN 1 | T12: Nhóm TPCN 2 | U12: Tổng | X12: Nhóm thuốc tân dược | Y12: Nhóm thuốc đông dược | Z12: Nhóm TPCN 1 | AA12: Nhóm TPCN 2 | AB12: Tổng | AE12: Nhóm thuốc tân dược | AF12: Nhóm thuốc đông dược | AG12: Nhóm TPCN 1 | AH12: Nhóm TPCN 2 | AI12: Tổng
C13: PHẠM CẢNH TÙNG | D13: MIỀN BẮC | F13: =F20+F26+F34+F44+F53+F60+F69+F78 -> 2.4999888e+09 | G13: =G20+G26+G34+G44+G53+G60+G69+G78 -> 1.9357481e+09 | H13: =H20+H26+H34+H44+H53+H60+H69+H78 -> 2.3888834e+09 | I13: =I20+I26+I34+I44+I53+I60+I69+I78 -> 2.2748735e+09 | J13: =J20+J26+J34+J44+J53+J60+J69+J78 -> 353000000 | K13: =K20+K26+K34+K44+K53+K60+K69+K78 -> 1412000000 | L13: =L20+L26+L34+L44+L53+L60+L69+L78 -> 1059000000 | M13: =M20+M26+M34+M44+M53+M60+M69+M78 -> 706000000 | ... AK13: =AK20+AK26+AK34+AK44+AK53+AK60+AK69+AK78 -> 530 | AL13: =V13-O13 -> 1000 | AM13: =AC13-V13 -> 1000 | AN13: =P13-'[14]THÁNG 7'!L11 -> 0
A14: 1 | B14: 1TDVHN008 | C14: Phùng Văn Hải | D14: Đông Anh, Mê Linh, Sóc Sơn. | E14: Hà nội | F14: =SUMIF('[14]DS đạt từ T1-4'!$D:$D,'Quý 3,2025'!$C14,'[14]DS đạt từ T1-4'!$AI:$AI) -> 85328810 | G14: =SUMIF('[14]DS đạt từ T1-4'!$D:$D,'Quý 3,2025'!$C14,'[14]DS đạt từ T1-4'!$AN:$AN) -> 73781857 | H14: =SUMIF([14]T5!D:D,'Quý 3,2025'!C14,[14]T5!AF:AF) -> 1.2030681e+08 | I14: =SUM(F14:H14)/$I$9 -> 93139159 | J14: =J$9*N14 -> 9500000 | K14: =K$9*N14 -> 38000000 | L14: =L$9*N14 -> 28500000 | M14: =M$9*N14 -> 19000000 | N14: 95000000 | O14: 240 | P14: 4 | Q14: =Q$9*U14 -> 10000000 | R14: =R$9*U14 -> 40000000 | S14: =S$9*U14 -> 30000000 | T14: =T$9*U14 -> 20000000 | U14: 100000000 | V14: 240 | W14: 3 | X14: =X$9*AB14 -> 10500000 | Y14: =Y$9*AB14 -> 42000000 | Z14: =Z$9*AB14 -> 31500000 | AA14: =AA$9*AB14 -> 21000000 | AB14: 105000000 | AC14: 260 | AD14: 2 | AE14: =SUMIF($J$12:$AB$12,AE$12,$J14:$AB14) -> 30000000 | AF14: =SUMIF($J$12:$AB$12,AF$12,$J14:$AB14) -> 120000000 | AG14: =SUMIF($J$12:$AB$12,AG$12,$J14:$AB14) -> 90000000 | AH14: =SUMIF($J$12:$AB$12,AH$12,$J14:$AB14) -> 60000000 | AI14: =SUMIF($J$12:$AB$12,AI$12,$J14:$AB14) -> 300000000 | AJ14: =SUMIF($J$11:$AD$11,AJ$11,$J14:$AD14) -> 740 | AK14: =SUMIF($J$11:$AD$11,AK$11,$J14:$AD14) -> 9 | AL14: =V14-O14 -> 0 | AM14: =AC14-V14 -> 20 | AN14: =P14-'[14]THÁNG 7'!L12 -> 0
A15: 2 | B15: 1TDVHN102 | C15: Lê Công Thắng | D15: Ba Vì, Sơn tây,Phúc Thọ | E15: Hà nội | F15: =SUMIF('[14]DS đạt từ T1-4'!$D:$D,'Quý 3,2025'!$C15,'[14]DS đạt từ T1-4'!$AI:$AI) -> 23842714 | G15: =SUMIF('[14]DS đạt từ T1-4'!$D:$D,'Quý 3,2025'!$C15,'[14]DS đạt từ T1-4'!$AN:$AN) -> 37276810 | H15: =SUMIF([14]T5!D:D,'Quý 3,2025'!C15,[14]T5!AF:AF) -> 18003857 | I15: =SUM(F15:H15)/$I$9 -> 26374460 | J15: =J$9*N15 -> 6000000 | K15: =K$9*N15 -> 24000000 | L15: =L$9*N15 -> 18000000 | M15: =M$9*N15 -> 12000000 | N15: 60000000 | O15: 180 | P15: 4 | Q15: =Q$9*U15 -> 6500000 | R15: =R$9*U15 -> 26000000 | S15: =S$9*U15 -> 19500000 | T15: =T$9*U15 -> 13000000 | U15: 65000000 | V15: 180 | W15: 3 | X15: =X$9*AB15 -> 7000000 | Y15: =Y$9*AB15 -> 28000000 | Z15: =Z$9*AB15 -> 21000000 | AA15: =AA$9*AB15 -> 14000000 | AB15: 70000000 | AC15: 200 | AD15: 2 | AE15: =SUMIF($J$12:$AB$12,AE$12,$J15:$AB15) -> 19500000 | AF15: =SUMIF($J$12:$AB$12,AF$12,$J15:$AB15) -> 78000000 | AG15: =SUMIF($J$12:$AB$12,AG$12,$J15:$AB15) -> 58500000 | AH15: =SUMIF($J$12:$AB$12,AH$12,$J15:$AB15) -> 39000000 | AI15: =SUMIF($J$12:$AB$12,AI$12,$J15:$AB15) -> 195000000 | AJ15: =SUMIF($J$11:$AD$11,AJ$11,$J15:$AD15) -> 560 | AK15: =SUMIF($J$11:$AD$11,AK$11,$J15:$AD15) -> 9 | AL15: =V15-O15 -> 0 | AM15: =AC15-V15 -> 20 | AN15: =P15-'[14]THÁNG 7'!L13 -> 0
A16: 3 | B16: 1TDVHN101 | C16: TDV Bắc | D16: Quốc Oai, Thạch Thất | E16: Hà nội | F16: 5555428.6 | G16: 3820000 | H16: 4212857.1 | I16: =SUM(F16:H16)/$I$9 -> 4529428.6 | J16: =J$9*N16 -> 3000000 | K16: =K$9*N16 -> 12000000 | L16: =L$9*N16 -> 9000000 | M16: =M$9*N16 -> 6000000 | N16: 30000000 | O16: 120 | P16: 5 | Q16: =Q$9*U16 -> 3000000 | R16: =R$9*U16 -> 12000000 | S16: =S$9*U16 -> 9000000 | T16: =T$9*U16 -> 6000000 | U16: 30000000 | V16: 160 | W16: 4 | X16: =X$9*AB16 -> 3500000 | Y16: =Y$9*AB16 -> 14000000 | Z16: =Z$9*AB16 -> 10500000 | AA16: =AA$9*AB16 -> 7000000 | AB16: 35000000 | AC16: 170 | AD16: 3 | AE16: =SUMIF($J$12:$AB$12,AE$12,$J16:$AB16) -> 9500000 | AF16: =SUMIF($J$12:$AB$12,AF$12,$J16:$AB16) -> 38000000 | AG16: =SUMIF($J$12:$AB$12,AG$12,$J16:$AB16) -> 28500000 | AH16: =SUMIF($J$12:$AB$12,AH$12,$J16:$AB16) -> 19000000 | AI16: =SUMIF($J$12:$AB$12,AI$12,$J16:$AB16) -> 95000000 | AJ16: =SUMIF($J$11:$AD$11,AJ$11,$J16:$AD16) -> 450 | AK16: =SUMIF($J$11:$AD$11,AK$11,$J16:$AD16) -> 12 | AL16: =V16-O16 -> 40 | AM16: =AC16-V16 -> 10 | AN16: =P16-'[14]THÁNG 7'!L14 -> 0
A17: 4 | B17: 1TDVHN084 | C17: Nguyễn thị Loan | D17: Mỹ Đức, Ứng hòa, Thanh Oai | E17: Hà nội | F17: =SUMIF('[14]DS đạt từ T1-4'!$D:$D,'Quý 3,2025'!$C17,'[14]DS đạt từ T1-4'!$AI:$AI) -> 90628381 | G17: =SUMIF('[14]DS đạt từ T1-4'!$D:$D,'Quý 3,2025'!$C17,'[14]DS đạt từ T1-4'!$AN:$AN) -> 31535238 | H17: =SUMIF([14]T5!D:D,'Quý 3,2025'!C17,[14]T5!AF:AF) -> 50718952 | I17: =SUM(F17:H17)/$I$9 -> 57627524 | J17: =J$9*N17 -> 6000000 | K17: =K$9*N17 -> 24000000 | L17: =L$9*N17 -> 18000000 | M17: =M$9*N17 -> 12000000 | N17: 60000000 | O17: 215 | P17: 3 | Q17: =Q$9*U17 -> 6500000 | R17: =R$9*U17 -> 26000000 | S17: =S$9*U17 -> 19500000 | T17: =T$9*U17 -> 13000000 | U17: 65000000 | V17: 215 | W17: 3 | X17: =X$9*AB17 -> 6500000 | Y17: =Y$9*AB17 -> 26000000 | Z17: =Z$9*AB17 -> 19500000 | AA17: =AA$9*AB17 -> 13000000 | AB17: 65000000 | AC17: 225 | AD17: 3 | AE17: =SUMIF($J$12:$AB$12,AE$12,$J17:$AB17) -> 19000000 | AF17: =SUMIF($J$12:$AB$12,AF$12,$J17:$AB17) -> 76000000 | AG17: =SUMIF($J$12:$AB$12,AG$12,$J17:$AB17) -> 57000000 | AH17: =SUMIF($J$12:$AB$12,AH$12,$J17:$AB17) -> 38000000 | AI17: =SUMIF($J$12:$AB$12,AI$12,$J17:$AB17) -> 190000000 | AJ17: =SUMIF($J$11:$AD$11,AJ$11,$J17:$AD17) -> 655 | AK17: =SUMIF($J$11:$AD$11,AK$11,$J17:$AD17) -> 9 | AL17: =V17-O17 -> 0 | AM17: =AC17-V17 -> 10 | AN17: =P17-'[14]THÁNG 7'!L15 -> 0
A18: 5 | B18: TDV02 | C18: Nguyễn Thị Minh Hương | D18: Thanh trì, Thường Tín, Phú xuyên | E18: Hà nội | F18: =SUMIF('[14]DS đạt từ T1-4'!$D:$D,'Quý 3,2025'!$C18,'[14]DS đạt từ T1-4'!$AI:$AI) -> 0 | G18: =SUMIF('[14]DS đạt từ T1-4'!$D:$D,'Quý 3,2025'!$C18,'[14]DS đạt từ T1-4'!$AN:$AN) -> 13929857 | H18: =SUMIF([14]T5!D:D,'Quý 3,2025'!C18,[14]T5!AF:AF) -> 15312000 | I18: =SUM(F18:H18)/$I$9 -> 9747285.7 | J18: =J$9*N18 -> 3000000 | K18: =K$9*N18 -> 12000000 | L18: =L$9*N18 -> 9000000 | M18: =M$9*N18 -> 6000000 | N18: 30000000 | O18: 100 | P18: 5 | Q18: =Q$9*U18 -> 3500000 | R18: =R$9*U18 -> 14000000 | S18: =S$9*U18 -> 10500000 | T18: =T$9*U18 -> 7000000 | U18: 35000000 | V18: 160 | W18: 4 | X18: =X$9*AB18 -> 4000000 | Y18: =Y$9*AB18 -> 16000000 | Z18: =Z$9*AB18 -> 12000000 | AA18: =AA$9*AB18 -> 8000000 | AB18: 40000000 | AC18: 170 | AD18: 3 | AE18: =SUMIF($J$12:$AB$12,AE$12,$J18:$AB18) -> 10500000 | AF18: =SUMIF($J$12:$AB$12,AF$12,$J18:$AB18) -> 42000000 | AG18: =SUMIF($J$12:$AB$12,AG$12,$J18:$AB18) -> 31500000 | AH18: =SUMIF($J$12:$AB$12,AH$12,$J18:$AB18) -> 21000000 | AI18: =SUMIF($J$12:$AB$12,AI$12,$J18:$AB18) -> 105000000 | AJ18: =SUMIF($J$11:$AD$11,AJ$11,$J18:$AD18) -> 430 | AK18: =SUMIF($J$11:$AD$11,AK$11,$J18:$AD18) -> 12 | AL18: =V18-O18 -> 60 | AM18: =AC18-V18 -> 10 | AN18: =P18-'[14]THÁNG 7'!L16 -> 0
A19: 6 | B19: 1TDVHN100 | C19: Nguyễn Thị Diệu Chi | D19: Đống Đa, Ba Đình, Tây Hồ | E19: Hà nội | F19: =SUMIF('[14]DS đạt từ T1-4'!$D:$D,'Quý 3,2025'!$C19,'[14]DS đạt từ T1-4'!$AI:$AI) -> 35889619 | G19: =SUMIF('[14]DS đạt từ T1-4'!$D:$D,'Quý 3,2025'!$C19,'[14]DS đạt từ T1-4'!$AN:$AN) -> 12635429 | H19: =SUMIF([14]T5!D:D,'Quý 3,2025'!C19,[14]T5!AF:AF) -> 42820714 | I19: =SUM(F19:H19)/$I$9 -> 30448587 | J19: =J$9*N19 -> 4000000 | K19: =K$9*N19 -> 16000000 | L19: =L$9*N19 -> 12000000 | M19: =M$9*N19 -> 8000000 | N19: 40000000 | O19: 100 | P19: 4 | Q19: =Q$9*U19 -> 4000000 | R19: =R$9*U19 -> 16000000 | S19: =S$9*U19 -> 12000000 | T19: =T$9*U19 -> 8000000 | U19: 40000000 | V19: 150 | W19: 4 | X19: =X$9*AB19 -> 4500000 | Y19: =Y$9*AB19 -> 18000000 | Z19: =Z$9*AB19 -> 13500000 | AA19: =AA$9*AB19 -> 9000000 | AB19: 45000000 | AC19: 170 | AD19: 3 | AE19: =SUMIF($J$12:$AB$12,AE$12,$J19:$AB19) -> 12500000 | AF19: =SUMIF($J$12:$AB$12,AF$12,$J19:$AB19) -> 50000000 | AG19: =SUMIF($J$12:$AB$12,AG$12,$J19:$AB19) -> 37500000 | AH19: =SUMIF($J$12:$AB$12,AH$12,$J19:$AB19) -> 25000000 | AI19: =SUMIF($J$12:$AB$12,AI$12,$J19:$AB19) -> 125000000 | AJ19: =SUMIF($J$11:$AD$11,AJ$11,$J19:$AD19) -> 420 | AK19: =SUMIF($J$11:$AD$11,AK$11,$J19:$AD19) -> 11 | AL19: =V19-O19 -> 50 | AM19: =AC19-V19 -> 20 | AN19: =P19-'[14]THÁNG 7'!L17 -> 0
A20: QLBH1 | F20: =SUM(F14:F19) -> 2.4124495e+08 | G20: =SUM(G14:G19) -> 1.7297919e+08 | H20: =SUM(H14:H19) -> 2.5137519e+08 | I20: =SUM(I14:I19) -> 2.2186644e+08 | J20: =SUM(J14:J19) -> 31500000 | K20: =SUM(K14:K19) -> 126000000 | L20: =SUM(L14:L19) -> 94500000 | M20: =SUM(M14:M19) -> 63000000 | ... AK20: =SUM(AK14:AK19) -> 62 | AL20: =V20-O20 -> 150 | AM20: =AC20-V20 -> 90 | AN20: =P20-'[14]THÁNG 7'!L18 -> 0
A21: 1 | B21: TDV03 | C21: Huỳnh Thị Yến | D21: Hà Đông Thanh Xuân, Chương Mỹ | E21: Hà nội | F21: =SUMIF('[14]DS đạt từ T1-4'!$D:$D,'Quý 3,2025'!$C21,'[14]DS đạt từ T1-4'!$AI:$AI) -> 0 | G21: =SUMIF('[14]DS đạt từ T1-4'!$D:$D,'Quý 3,2025'!$C21,'[14]DS đạt từ T1-4'!$AN:$AN) -> 0 | H21: 19251143 | I21: =SUM(F21:H21)/$I$9 -> 6417047.6 | J21: =J$9*N21 -> 6000000 | K21: =K$9*N21 -> 24000000 | L21: =L$9*N21 -> 18000000 | M21: =M$9*N21 -> 12000000 | N21: 60000000 | O21: 120 | P21: 4 | Q21: =Q$9*U21 -> 6000000 | R21: =R$9*U21 -> 24000000 | S21: =S$9*U21 -> 18000000 | T21: =T$9*U21 -> 12000000 | U21: 60000000 | V21: 150 | W21: 4 | X21: =X$9*AB21 -> 6500000 | Y21: =Y$9*AB21 -> 26000000 | Z21: =Z$9*AB21 -> 19500000 | AA21: =AA$9*AB21 -> 13000000 | AB21: 65000000 | AC21: 170 | AD21: 3 | AE21: =SUMIF($J$12:$AB$12,AE$12,$J21:$AB21) -> 18500000 | AF21: =SUMIF($J$12:$AB$12,AF$12,$J21:$AB21) -> 74000000 | AG21: =SUMIF($J$12:$AB$12,AG$12,$J21:$AB21) -> 55500000 | AH21: =SUMIF($J$12:$AB$12,AH$12,$J21:$AB21) -> 37000000 | AI21: =SUMIF($J$12:$AB$12,AI$12,$J21:$AB21) -> 185000000 | AJ21: =SUMIF($J$11:$AD$11,AJ$11,$J21:$AD21) -> 440 | AK21: =SUMIF($J$11:$AD$11,AK$11,$J21:$AD21) -> 11 | AL21: =V21-O21 -> 30 | AM21: =AC21-V21 -> 20 | AN21: =P21-'[14]THÁNG 7'!L19 -> 0
A22: 2 | B22: 1TDVHN005 | C22: Hoàng Thị Thu Hà | D22: Hoàng Mai, Hai Bà Trưng, Hoàn Kiếm | E22: Hà nội | F22: =SUMIF('[14]DS đạt từ T1-4'!$D:$D,'Quý 3,2025'!$C22,'[14]DS đạt từ T1-4'!$AI:$AI) -> 82167571 | G22: =SUMIF('[14]DS đạt từ T1-4'!$D:$D,'Quý 3,2025'!$C22,'[14]DS đạt từ T1-4'!$AN:$AN) -> 71514571 | H22: =SUMIF([14]T5!D:D,'Quý 3,2025'!C22,[14]T5!AF:AF) -> 95590714 | I22: =SUM(F22:H22)/$I$9 -> 83090952 | J22: =J$9*N22 -> 9000000 | K22: =K$9*N22 -> 36000000 | L22: =L$9*N22 -> 27000000 | M22: =M$9*N22 -> 18000000 | N22: 90000000 | O22: 230 | P22: 2 | Q22: =Q$9*U22 -> 9500000 | R22: =R$9*U22 -> 38000000 | S22: =S$9*U22 -> 28500000 | T22: =T$9*U22 -> 19000000 | U22: 95000000 | V22: 250 | W22: 2 | X22: =X$9*AB22 -> 9500000 | Y22: =Y$9*AB22 -> 38000000 | Z22: =Z$9*AB22 -> 28500000 | AA22: =AA$9*AB22 -> 19000000 | AB22: 95000000 | AC22: 270 | AD22: 2 | AE22: =SUMIF($J$12:$AB$12,AE$12,$J22:$AB22) -> 28000000 | AF22: =SUMIF($J$12:$AB$12,AF$12,$J22:$AB22) -> 112000000 | AG22: =SUMIF($J$12:$AB$12,AG$12,$J22:$AB22) -> 84000000 | AH22: =SUMIF($J$12:$AB$12,AH$12,$J22:$AB22) -> 56000000 | AI22: =SUMIF($J$12:$AB$12,AI$12,$J22:$AB22) -> 280000000 | AJ22: =SUMIF($J$11:$AD$11,AJ$11,$J22:$AD22) -> 750 | AK22: =SUMIF($J$11:$AD$11,AK$11,$J22:$AD22) -> 6 | AL22: =V22-O22 -> 20 | AM22: =AC22-V22 -> 20 | AN22: =P22-'[14]THÁNG 7'!L20 -> 0
A23: 3 | B23: TDV04 | C23: Bùi Thị Thu Hường | D23: Gia Lâm, Long Biên | E23: Hà nội | F23: 16130762 | G23: 7165000 | H23: 6958571.4 | I23: =SUM(F23:H23)/$I$9 -> 10084778 | J23: =J$9*N23 -> 3000000 | K23: =K$9*N23 -> 12000000 | L23: =L$9*N23 -> 9000000 | M23: =M$9*N23 -> 6000000 | N23: 30000000 | O23: 100 | P23: 3 | Q23: =Q$9*U23 -> 3500000 | R23: =R$9*U23 -> 14000000 | S23: =S$9*U23 -> 10500000 | T23: =T$9*U23 -> 7000000 | U23: 35000000 | V23: 140 | W23: 3 | X23: =X$9*AB23 -> 4000000 | Y23: =Y$9*AB23 -> 16000000 | Z23: =Z$9*AB23 -> 12000000 | AA23: =AA$9*AB23 -> 8000000 | AB23: 40000000 | AC23: 150 | AD23: 4 | AE23: =SUMIF($J$12:$AB$12,AE$12,$J23:$AB23) -> 10500000 | AF23: =SUMIF($J$12:$AB$12,AF$12,$J23:$AB23) -> 42000000 | AG23: =SUMIF($J$12:$AB$12,AG$12,$J23:$AB23) -> 31500000 | AH23: =SUMIF($J$12:$AB$12,AH$12,$J23:$AB23) -> 21000000 | AI23: =SUMIF($J$12:$AB$12,AI$12,$J23:$AB23) -> 105000000 | AJ23: =SUMIF($J$11:$AD$11,AJ$11,$J23:$AD23) -> 390 | AK23: =SUMIF($J$11:$AD$11,AK$11,$J23:$AD23) -> 10 | AL23: =V23-O23 -> 40 | AM23: =AC23-V23 -> 10 | AN23: =P23-'[14]THÁNG 7'!L21 -> 0
A24: 4 | B24: TDV01 | C24: Đỗ Ngọc Minh | D24: Đan Phượng, Hoài Đức | E24: Hà nội | F24: 12266429 | G24: =SUMIF('[14]DS đạt từ T1-4'!$D:$D,'Quý 3,2025'!$C24,'[14]DS đạt từ T1-4'!$AN:$AN) -> 0 | H24: 9697857.1 | I24: =SUM(F24:H24)/$I$9 -> 7321428.6 | J24: =J$9*N24 -> 3000000 | K24: =K$9*N24 -> 12000000 | L24: =L$9*N24 -> 9000000 | M24: =M$9*N24 -> 6000000 | N24: 30000000 | O24: 100 | P24: 4 | Q24: =Q$9*U24 -> 3500000 | R24: =R$9*U24 -> 14000000 | S24: =S$9*U24 -> 10500000 | T24: =T$9*U24 -> 7000000 | U24: 35000000 | V24: 130 | W24: 4 | X24: =X$9*AB24 -> 4000000 | Y24: =Y$9*AB24 -> 16000000 | Z24: =Z$9*AB24 -> 12000000 | AA24: =AA$9*AB24 -> 8000000 | AB24: 40000000 | AC24: 150 | AD24: 3 | AE24: =SUMIF($J$12:$AB$12,AE$12,$J24:$AB24) -> 10500000 | AF24: =SUMIF($J$12:$AB$12,AF$12,$J24:$AB24) -> 42000000 | AG24: =SUMIF($J$12:$AB$12,AG$12,$J24:$AB24) -> 31500000 | AH24: =SUMIF($J$12:$AB$12,AH$12,$J24:$AB24) -> 21000000 | AI24: =SUMIF($J$12:$AB$12,AI$12,$J24:$AB24) -> 105000000 | AJ24: =SUMIF($J$11:$AD$11,AJ$11,$J24:$AD24) -> 380 | AK24: =SUMIF($J$11:$AD$11,AK$11,$J24:$AD24) -> 11 | AL24: =V24-O24 -> 30 | AM24: =AC24-V24 -> 20 | AN24: =P24-'[14]THÁNG 7'!L22 -> 0
A25: 5 | B25: 1TDVHN006 | C25: Phan Thị Phương Hoa | D25: Cầu Giấy, Nam Từ Liêm, Bắc Từ Liêm | E25: Hà nội | F25: =SUMIF('[14]DS đạt từ T1-4'!$D:$D,'Quý 3,2025'!$C25,'[14]DS đạt từ T1-4'!$AI:$AI) -> 55122619 | G25: =SUMIF('[14]DS đạt từ T1-4'!$D:$D,'Quý 3,2025'!$C25,'[14]DS đạt từ T1-4'!$AN:$AN) -> 36120714 | H25: =SUMIF([14]T5!D:D,'Quý 3,2025'!C25,[14]T5!AF:AF) -> 36502857 | I25: =SUM(F25:H25)/$I$9 -> 42582063 | J25: =J$9*N25 -> 6000000 | K25: =K$9*N25 -> 24000000 | L25: =L$9*N25 -> 18000000 | M25: =M$9*N25 -> 12000000 | N25: 60000000 | O25: 170 | P25: 3 | Q25: =Q$9*U25 -> 6000000 | R25: =R$9*U25 -> 24000000 | S25: =S$9*U25 -> 18000000 | T25: =T$9*U25 -> 12000000 | U25: 60000000 | V25: 170 | W25: 3 | X25: =X$9*AB25 -> 6500000 | Y25: =Y$9*AB25 -> 26000000 | Z25: =Z$9*AB25 -> 19500000 | AA25: =AA$9*AB25 -> 13000000 | AB25: 65000000 | AC25: 190 | AD25: 2 | AE25: =SUMIF($J$12:$AB$12,AE$12,$J25:$AB25) -> 18500000 | AF25: =SUMIF($J$12:$AB$12,AF$12,$J25:$AB25) -> 74000000 | AG25: =SUMIF($J$12:$AB$12,AG$12,$J25:$AB25) -> 55500000 | AH25: =SUMIF($J$12:$AB$12,AH$12,$J25:$AB25) -> 37000000 | AI25: =SUMIF($J$12:$AB$12,AI$12,$J25:$AB25) -> 185000000 | AJ25: =SUMIF($J$11:$AD$11,AJ$11,$J25:$AD25) -> 530 | AK25: =SUMIF($J$11:$AD$11,AK$11,$J25:$AD25) -> 8 | AL25: =V25-O25 -> 0 | AM25: =AC25-V25 -> 20 | AN25: =P25-'[14]THÁNG 7'!L23 -> 0
A26: QLBH2 | C26: Nguyễn Mạnh Thắng | F26: =SUM(F21:F25) -> 1.6568738e+08 | G26: =SUM(G21:G25) -> 1.1480029e+08 | H26: =SUM(H21:H25) -> 1.6800114e+08 | I26: =SUM(I21:I25) -> 1.4949627e+08 | J26: =SUM(J21:J25) -> 27000000 | K26: =SUM(K21:K25) -> 108000000 | L26: =SUM(L21:L25) -> 81000000 | M26: =SUM(M21:M25) -> 54000000 | ... AK26: =SUM(AK21:AK25) -> 46 | AL26: =V26-O26 -> 120 | AM26: =AC26-V26 -> 90 | AN26: =P26-'[14]THÁNG 7'!L24 -> 0
A27: 1 | B27: TDV178 | C27: Ngô Thị Mường Khương | D27: Huyện Thủy Nguyên, Quận Hồng Bàng,Quận Lê Chân,Huyện An Dương,Quận Hải An, Quận Ngô Quyền | E27: Hải Phòng 1 | F27: =SUMIF('[14]DS đạt từ T1-4'!$D:$D,'Quý 3,2025'!$C27,'[14]DS đạt từ T1-4'!$AI:$AI) -> 39091000 | G27: =SUMIF('[14]DS đạt từ T1-4'!$D:$D,'Quý 3,2025'!$C27,'[14]DS đạt từ T1-4'!$AN:$AN) -> 22580857 | H27: =SUMIF([14]T5!D:D,'Quý 3,2025'!C27,[14]T5!AF:AF) -> 61125429 | I27: =SUM(F27:H27)/$I$9 -> 40932429 | J27: =J$9*N27 -> 6000000 | K27: =K$9*N27 -> 24000000 | L27: =L$9*N27 -> 18000000 | M27: =M$9*N27 -> 12000000 | N27: 60000000 | O27: 250 | P27: 3 | Q27: =Q$9*U27 -> 6500000 | R27: =R$9*U27 -> 26000000 | S27: =S$9*U27 -> 19500000 | T27: =T$9*U27 -> 13000000 | U27: 65000000 | V27: 270 | W27: 3 | X27: =X$9*AB27 -> 7000000 | Y27: =Y$9*AB27 -> 28000000 | Z27: =Z$9*AB27 -> 21000000 | AA27: =AA$9*AB27 -> 14000000 | AB27: 70000000 | AC27: 290 | AD27: 2 | AE27: =SUMIF($J$12:$AB$12,AE$12,$J27:$AB27) -> 19500000 | AF27: =SUMIF($J$12:$AB$12,AF$12,$J27:$AB27) -> 78000000 | AG27: =SUMIF($J$12:$AB$12,AG$12,$J27:$AB27) -> 58500000 | AH27: =SUMIF($J$12:$AB$12,AH$12,$J27:$AB27) -> 39000000 | AI27: =SUMIF($J$12:$AB$12,AI$12,$J27:$AB27) -> 195000000 | AJ27: =SUMIF($J$11:$AD$11,AJ$11,$J27:$AD27) -> 810 | AK27: =SUMIF($J$11:$AD$11,AK$11,$J27:$AD27) -> 8 | AL27: =V27-O27 -> 20 | AM27: =AC27-V27 -> 20 | AN27: =P27-'[14]THÁNG 7'!L25 -> 0
A28: 2 | B28: TDV174 | C28: Đinh Ngọc Dương | D28: Quận Đồ Sơn, Huyện Kiến Thụy, Quận Dương Kinh, Quận Kiến An, Huyện An Lão,Huyện Vĩnh Bảo,Huyện Tiên Lãng | E28: Hải Phòng 2 | G28: 3034285.7 | H28: =SUMIF([14]T5!D:D,'Quý 3,2025'!C28,[14]T5!AF:AF) -> 296190.48 | I28: =SUM(F28:H28)/$I$9 -> 1110158.7 | J28: =J$9*N28 -> 5500000 | K28: =K$9*N28 -> 22000000 | L28: =L$9*N28 -> 16500000 | M28: =M$9*N28 -> 11000000 | N28: 55000000 | O28: 220 | P28: 4 | Q28: =Q$9*U28 -> 6000000 | R28: =R$9*U28 -> 24000000 | S28: =S$9*U28 -> 18000000 | T28: =T$9*U28 -> 12000000 | U28: 60000000 | V28: 240 | W28: 4 | X28: =X$9*AB28 -> 6000000 | Y28: =Y$9*AB28 -> 24000000 | Z28: =Z$9*AB28 -> 18000000 | AA28: =AA$9*AB28 -> 12000000 | AB28: 60000000 | AC28: 260 | AD28: 3 | AE28: =SUMIF($J$12:$AB$12,AE$12,$J28:$AB28) -> 17500000 | AF28: =SUMIF($J$12:$AB$12,AF$12,$J28:$AB28) -> 70000000 | AG28: =SUMIF($J$12:$AB$12,AG$12,$J28:$AB28) -> 52500000 | AH28: =SUMIF($J$12:$AB$12,AH$12,$J28:$AB28) -> 35000000 | AI28: =SUMIF($J$12:$AB$12,AI$12,$J28:$AB28) -> 175000000 | AJ28: =SUMIF($J$11:$AD$11,AJ$11,$J28:$AD28) -> 720 | AK28: =SUMIF($J$11:$AD$11,AK$11,$J28:$AD28) -> 11 | AL28: =V28-O28 -> 20 | AM28: =AC28-V28 -> 20 | AN28: =P28-'[14]THÁNG 7'!L26 -> 0
A29: 3 | B29: TDV184 | C29: Nguyễn Khắc Mạnh | D29: Trong hệ thống Công ty CP dược phẩm Hải Phòng(Hiệu Thuốc Hải Phòng) | E29: Hải Phòng 3 | F29: =SUMIF('[14]DS đạt từ T1-4'!$D:$D,'Quý 3,2025'!$C29,'[14]DS đạt từ T1-4'!$AI:$AI) -> 75431333 | G29: =SUMIF('[14]DS đạt từ T1-4'!$D:$D,'Quý 3,2025'!$C29,'[14]DS đạt từ T1-4'!$AN:$AN) -> 88289571 | H29: =SUMIF([14]T5!D:D,'Quý 3,2025'!C29,[14]T5!AF:AF) -> 86784619 | I29: =SUM(F29:H29)/$I$9 -> 83501841 | J29: =J$9*N29 -> 8000000 | K29: =K$9*N29 -> 32000000 | L29: =L$9*N29 -> 24000000 | M29: =M$9*N29 -> 16000000 | N29: 80000000 | O29: 380 | P29: 4 | Q29: =Q$9*U29 -> 8500000 | R29: =R$9*U29 -> 34000000 | S29: =S$9*U29 -> 25500000 | T29: =T$9*U29 -> 17000000 | U29: 85000000 | V29: 400 | W29: 3 | X29: =X$9*AB29 -> 9000000 | Y29: =Y$9*AB29 -> 36000000 | Z29: =Z$9*AB29 -> 27000000 | AA29: =AA$9*AB29 -> 18000000 | AB29: 90000000 | AC29: 400 | AD29: 3 | AE29: =SUMIF($J$12:$AB$12,AE$12,$J29:$AB29) -> 25500000 | AF29: =SUMIF($J$12:$AB$12,AF$12,$J29:$AB29) -> 102000000 | AG29: =SUMIF($J$12:$AB$12,AG$12,$J29:$AB29) -> 76500000 | AH29: =SUMIF($J$12:$AB$12,AH$12,$J29:$AB29) -> 51000000 | AI29: =SUMIF($J$12:$AB$12,AI$12,$J29:$AB29) -> 255000000 | AJ29: =SUMIF($J$11:$AD$11,AJ$11,$J29:$AD29) -> 1180 | AK29: =SUMIF($J$11:$AD$11,AK$11,$J29:$AD29) -> 10 | AL29: =V29-O29 -> 20 | AM29: =AC29-V29 -> 0 | AN29: =P29-'[14]THÁNG 7'!L27 -> 0
A30: 4 | B30: TDV139 | C30: Nguyễn Hữu Nam | D30: TP Chí Linh, TX Kinh Môn, Huyện Kim Thành, Huyện Thanh Hà,Huyện Nam Sách, 1/2 TP Hải Dương(Phường ái quốc, phường nam đồng, phường ngọc châu, phường phạm ngũ lão,phường quang trung,phường trần hưng đạo,phường trần phú, phường tân hưng,phường nguyễn trãi) | E30: Hải Dương 1 | F30: =SUMIF('[14]DS đạt từ T1-4'!$D:$D,'Quý 3,2025'!$C30,'[14]DS đạt từ T1-4'!$AI:$AI) -> 27666429 | G30: =SUMIF('[14]DS đạt từ T1-4'!$D:$D,'Quý 3,2025'!$C30,'[14]DS đạt từ T1-4'!$AN:$AN) -> 33371667 | H30: =SUMIF([14]T5!D:D,'Quý 3,2025'!C30,[14]T5!AF:AF) -> 51906762 | I30: =SUM(F30:H30)/$I$9 -> 37648286 | J30: =J$9*N30 -> 6000000 | K30: =K$9*N30 -> 24000000 | L30: =L$9*N30 -> 18000000 | M30: =M$9*N30 -> 12000000 | N30: 60000000 | O30: 270 | P30: 6 | Q30: =Q$9*U30 -> 6500000 | R30: =R$9*U30 -> 26000000 | S30: =S$9*U30 -> 19500000 | T30: =T$9*U30 -> 13000000 | U30: 65000000 | V30: 270 | W30: 5 | X30: =X$9*AB30 -> 7000000 | Y30: =Y$9*AB30 -> 28000000 | Z30: =Z$9*AB30 -> 21000000 | AA30: =AA$9*AB30 -> 14000000 | AB30: 70000000 | AC30: 290 | AD30: 3 | AE30: =SUMIF($J$12:$AB$12,AE$12,$J30:$AB30) -> 19500000 | AF30: =SUMIF($J$12:$AB$12,AF$12,$J30:$AB30) -> 78000000 | AG30: =SUMIF($J$12:$AB$12,AG$12,$J30:$AB30) -> 58500000 | AH30: =SUMIF($J$12:$AB$12,AH$12,$J30:$AB30) -> 39000000 | AI30: =SUMIF($J$12:$AB$12,AI$12,$J30:$AB30) -> 195000000 | AJ30: =SUMIF($J$11:$AD$11,AJ$11,$J30:$AD30) -> 830 | AK30: =SUMIF($J$11:$AD$11,AK$11,$J30:$AD30) -> 14 | AL30: =V30-O30 -> 0 | AM30: =AC30-V30 -> 20 | AN30: =P30-'[14]THÁNG 7'!L28 -> 0
A31: 5 | B31: TDV05 | C31: TDV Dân | D31: Huyện Ninh Giang, Huyện Tứ Kỳ, Huyện Bình Giang, Huyện Cẩm giàng,Huyện Thanh Miện,Huyện Gia Lộc, 1/2 TP Hải Dương(phường việt hòa,phường thanh bình,phường tứ minh, xã thạch khôi, việt hà, cẩm thượng,hải tân, p.tân bình,lê thanh nghị) | E31: Hải Dương 2 | F31: =SUMIF('[14]DS đạt từ T1-4'!$D:$D,'Quý 3,2025'!$C31,'[14]DS đạt từ T1-4'!$AI:$AI) -> 0 | G31: =SUMIF('[14]DS đạt từ T1-4'!$D:$D,'Quý 3,2025'!$C31,'[14]DS đạt từ T1-4'!$AN:$AN) -> 0 | H31: =SUMIF([14]T5!D:D,'Quý 3,2025'!C31,[14]T5!AF:AF) -> 0 | I31: =SUM(F31:H31)/$I$9 -> 0 | J31: =J$9*N31 -> 5000000 | K31: =K$9*N31 -> 20000000 | L31: =L$9*N31 -> 15000000 | M31: =M$9*N31 -> 10000000 | N31: 50000000 | O31: 180 | P31: 6 | Q31: =Q$9*U31 -> 5500000 | R31: =R$9*U31 -> 22000000 | S31: =S$9*U31 -> 16500000 | T31: =T$9*U31 -> 11000000 | U31: 55000000 | V31: 200 | W31: 6 | X31: =X$9*AB31 -> 5500000 | Y31: =Y$9*AB31 -> 22000000 | Z31: =Z$9*AB31 -> 16500000 | AA31: =AA$9*AB31 -> 11000000 | AB31: 55000000 | AC31: 245 | AD31: 5 | AE31: =SUMIF($J$12:$AB$12,AE$12,$J31:$AB31) -> 16000000 | AF31: =SUMIF($J$12:$AB$12,AF$12,$J31:$AB31) -> 64000000 | AG31: =SUMIF($J$12:$AB$12,AG$12,$J31:$AB31) -> 48000000 | AH31: =SUMIF($J$12:$AB$12,AH$12,$J31:$AB31) -> 32000000 | AI31: =SUMIF($J$12:$AB$12,AI$12,$J31:$AB31) -> 160000000 | AJ31: =SUMIF($J$11:$AD$11,AJ$11,$J31:$AD31) -> 625 | AK31: =SUMIF($J$11:$AD$11,AK$11,$J31:$AD31) -> 17 | AL31: =V31-O31 -> 20 | AM31: =AC31-V31 -> 45 | AN31: =P31-'[14]THÁNG 7'!L29 -> 0
A32: 6 | B32: TDV168 | C32: Đinh Quang Phúc | D32: TP Hạ Long, TP Cẩm Phả, TX Cửa Ông, H Vân Đồn | E32: Quảng Ninh 1 | F32: =SUMIF('[14]DS đạt từ T1-4'!$D:$D,'Quý 3,2025'!$C32,'[14]DS đạt từ T1-4'!$AI:$AI) -> 56947571 | G32: =SUMIF('[14]DS đạt từ T1-4'!$D:$D,'Quý 3,2025'!$C32,'[14]DS đạt từ T1-4'!$AN:$AN) -> 22177857 | H32: =SUMIF([14]T5!D:D,'Quý 3,2025'!C32,[14]T5!AF:AF) -> 36784571 | I32: =SUM(F32:H32)/$I$9 -> 38636667 | J32: =J$9*N32 -> 5500000 | K32: =K$9*N32 -> 22000000 | L32: =L$9*N32 -> 16500000 | M32: =M$9*N32 -> 11000000 | N32: 55000000 | O32: 170 | P32: 5 | Q32: =Q$9*U32 -> 6000000 | R32: =R$9*U32 -> 24000000 | S32: =S$9*U32 -> 18000000 | T32: =T$9*U32 -> 12000000 | U32: 60000000 | V32: 200 | W32: 4 | X32: =X$9*AB32 -> 6500000 | Y32: =Y$9*AB32 -> 26000000 | Z32: =Z$9*AB32 -> 19500000 | AA32: =AA$9*AB32 -> 13000000 | AB32: 65000000 | AC32: 220 | AD32: 4 | AE32: =SUMIF($J$12:$AB$12,AE$12,$J32:$AB32) -> 18000000 | AF32: =SUMIF($J$12:$AB$12,AF$12,$J32:$AB32) -> 72000000 | AG32: =SUMIF($J$12:$AB$12,AG$12,$J32:$AB32) -> 54000000 | AH32: =SUMIF($J$12:$AB$12,AH$12,$J32:$AB32) -> 36000000 | AI32: =SUMIF($J$12:$AB$12,AI$12,$J32:$AB32) -> 180000000 | AJ32: =SUMIF($J$11:$AD$11,AJ$11,$J32:$AD32) -> 590 | AK32: =SUMIF($J$11:$AD$11,AK$11,$J32:$AD32) -> 13 | AL32: =V32-O32 -> 30 | AM32: =AC32-V32 -> 20 | AN32: =P32-'[14]THÁNG 7'!L30 -> 0
A33: 7 | B33: TDV06 | C33: Nguyễn Văn Xuân | D33: TP Móng Cái, H Hải Hà, H Đầm Hà, H Tiên Yên, H Bình Liêu, H Ba Chẽ | E33: Quảng Ninh 2 | F33: =SUMIF('[14]DS đạt từ T1-4'!$D:$D,'Quý 3,2025'!$C33,'[14]DS đạt từ T1-4'!$AI:$AI) -> 9818809.5 | G33: =SUMIF('[14]DS đạt từ T1-4'!$D:$D,'Quý 3,2025'!$C33,'[14]DS đạt từ T1-4'!$AN:$AN) -> 7600000 | H33: =SUMIF([14]T5!D:D,'Quý 3,2025'!C33,[14]T5!AF:AF) -> 9682142.9 | I33: =SUM(F33:H33)/$I$9 -> 9033650.8 | J33: =J$9*N33 -> 5000000 | K33: =K$9*N33 -> 20000000 | L33: =L$9*N33 -> 15000000 | M33: =M$9*N33 -> 10000000 | N33: 50000000 | O33: 150 | P33: 4 | Q33: =Q$9*U33 -> 5500000 | R33: =R$9*U33 -> 22000000 | S33: =S$9*U33 -> 16500000 | T33: =T$9*U33 -> 11000000 | U33: 55000000 | V33: 180 | W33: 4 | X33: =X$9*AB33 -> 5500000 | Y33: =Y$9*AB33 -> 22000000 | Z33: =Z$9*AB33 -> 16500000 | AA33: =AA$9*AB33 -> 11000000 | AB33: 55000000 | AC33: 200 | AD33: 4 | AE33: =SUMIF($J$12:$AB$12,AE$12,$J33:$AB33) -> 16000000 | AF33: =SUMIF($J$12:$AB$12,AF$12,$J33:$AB33) -> 64000000 | AG33: =SUMIF($J$12:$AB$12,AG$12,$J33:$AB33) -> 48000000 | AH33: =SUMIF($J$12:$AB$12,AH$12,$J33:$AB33) -> 32000000 | AI33: =SUMIF($J$12:$AB$12,AI$12,$J33:$AB33) -> 160000000 | AJ33: =SUMIF($J$11:$AD$11,AJ$11,$J33:$AD33) -> 530 | AK33: =SUMIF($J$11:$AD$11,AK$11,$J33:$AD33) -> 12 | AL33: =V33-O33 -> 30 | AM33: =AC33-V33 -> 20 | AN33: =P33-'[14]THÁNG 7'!L31 -> 0
A34: QLBH3 | C34: Lê Văn Thành | F34: =SUM(F27:F33) -> 2.0895514e+08 | G34: =SUM(G27:G33) -> 1.7705424e+08 | H34: =SUM(H27:H33) -> 2.4657971e+08 | I34: =SUM(I27:I33) -> 2.1086303e+08 | J34: =SUM(J27:J33) -> 41000000 | K34: =SUM(K27:K33) -> 164000000 | L34: =SUM(L27:L33) -> 123000000 | M34: =SUM(M27:M33) -> 82000000 | ... AK34: =SUM(AK27:AK33) -> 85 | AL34: =V34-O34 -> 140 | AM34: =AC34-V34 -> 145 | AN34: =P34-'[14]THÁNG 7'!L32 -> 0
A35: 1 | B35: TDV188 | C35: Tuyển TDV mới | D35: Sông công, Phổ yên,phú bình,võ nhai,1/2Thành phố(P. tích lương, p.trung thành, p.trưng vương, p.túc duyên, x.cao ngạn, x.đồng liên, x.hống thượng, p.cam giá, p.chùa hang, p.đồng bẩm, p.đồng quang, p.gia sàng, p.hoàng văn thụ, p.hương sơn, p.phan đình phùng, p.phú xá, p.tân thành) | E35: Thái Nguyên 1 | F35: 51776143 | G35: 13790000 | H35: 35206429 | I35: =SUM(F35:H35)/$I$9 -> 33590857 | J35: =J$9*N35 -> 5000000 | K35: =K$9*N35 -> 20000000 | L35: =L$9*N35 -> 15000000 | M35: =M$9*N35 -> 10000000 | N35: 50000000 | O35: 250 | P35: 4 | Q35: =Q$9*U35 -> 5500000 | R35: =R$9*U35 -> 22000000 | S35: =S$9*U35 -> 16500000 | T35: =T$9*U35 -> 11000000 | U35: 55000000 | V35: 250 | W35: 3 | X35: =X$9*AB35 -> 6000000 | Y35: =Y$9*AB35 -> 24000000 | Z35: =Z$9*AB35 -> 18000000 | AA35: =AA$9*AB35 -> 12000000 | AB35: 60000000 | AC35: 250 | AD35: 2 | AE35: =SUMIF($J$12:$AB$12,AE$12,$J35:$AB35) -> 16500000 | AF35: =SUMIF($J$12:$AB$12,AF$12,$J35:$AB35) -> 66000000 | AG35: =SUMIF($J$12:$AB$12,AG$12,$J35:$AB35) -> 49500000 | AH35: =SUMIF($J$12:$AB$12,AH$12,$J35:$AB35) -> 33000000 | AI35: =SUMIF($J$12:$AB$12,AI$12,$J35:$AB35) -> 165000000 | AJ35: =SUMIF($J$11:$AD$11,AJ$11,$J35:$AD35) -> 750 | AK35: =SUMIF($J$11:$AD$11,AK$11,$J35:$AD35) -> 9 | AL35: =V35-O35 -> 0 | AM35: =AC35-V35 -> 0 | AN35: =P35-'[14]THÁNG 7'!L33 -> 0
A36: 2 | B36: TDV07 | C36: Phạm Đình Thăng | D36: Đại từ, phú lương, định hóa, đồng hỉ, 1/2 thành phố(p.thịnh đán, x.cao ngạn, x.linh sơn, x.phúc hà, x.phúc trìu, x.phúc xuân, x.quyết thắng, x.sơn cẩm, p.quang trung, p.quang vinh, p.quán triều, p.tân long, p.tân lập, p.tân thịnh) | E36: Thái Nguyên 2 | F36: =SUMIF('[14]DS đạt từ T1-4'!$D:$D,'Quý 3,2025'!$C36,'[14]DS đạt từ T1-4'!$AI:$AI) -> 51048571 | G36: =SUMIF('[14]DS đạt từ T1-4'!$D:$D,'Quý 3,2025'!$C36,'[14]DS đạt từ T1-4'!$AN:$AN) -> 20794286 | H36: =SUMIF([14]T5!D:D,'Quý 3,2025'!C36,[14]T5!AF:AF) -> 35833857 | I36: =SUM(F36:H36)/$I$9 -> 35892238 | J36: =J$9*N36 -> 5000000 | K36: =K$9*N36 -> 20000000 | L36: =L$9*N36 -> 15000000 | M36: =M$9*N36 -> 10000000 | N36: 50000000 | O36: 250 | P36: 3 | Q36: =Q$9*U36 -> 5500000 | R36: =R$9*U36 -> 22000000 | S36: =S$9*U36 -> 16500000 | T36: =T$9*U36 -> 11000000 | U36: 55000000 | V36: 250 | W36: 3 | X36: =X$9*AB36 -> 6000000 | Y36: =Y$9*AB36 -> 24000000 | Z36: =Z$9*AB36 -> 18000000 | AA36: =AA$9*AB36 -> 12000000 | AB36: 60000000 | AC36: 250 | AD36: 2 | AE36: =SUMIF($J$12:$AB$12,AE$12,$J36:$AB36) -> 16500000 | AF36: =SUMIF($J$12:$AB$12,AF$12,$J36:$AB36) -> 66000000 | AG36: =SUMIF($J$12:$AB$12,AG$12,$J36:$AB36) -> 49500000 | AH36: =SUMIF($J$12:$AB$12,AH$12,$J36:$AB36) -> 33000000 | AI36: =SUMIF($J$12:$AB$12,AI$12,$J36:$AB36) -> 165000000 | AJ36: =SUMIF($J$11:$AD$11,AJ$11,$J36:$AD36) -> 750 | AK36: =SUMIF($J$11:$AD$11,AK$11,$J36:$AD36) -> 8 | AL36: =V36-O36 -> 0 | AM36: =AC36-V36 -> 0 | AN36: =P36-'[14]THÁNG 7'!L34 -> 0
A37: 3 | B37: TDV033 | C37: Quách Đăng Khiêm | D37: Lạng Giang, Tân Yên, Việt Yên, Việt hòa, Thành phố | E37: Bắc Giang 1 | F37: =SUMIF('[14]DS đạt từ T1-4'!$D:$D,'Quý 3,2025'!$C37,'[14]DS đạt từ T1-4'!$AI:$AI) -> 68412381 | G37: =SUMIF('[14]DS đạt từ T1-4'!$D:$D,'Quý 3,2025'!$C37,'[14]DS đạt từ T1-4'!$AN:$AN) -> 80407190 | H37: =SUMIF([14]T5!D:D,'Quý 3,2025'!C37,[14]T5!AF:AF) -> 82926381 | I37: =SUM(F37:H37)/$I$9 -> 77248651 | J37: =J$9*N37 -> 8000000 | K37: =K$9*N37 -> 32000000 | L37: =L$9*N37 -> 24000000 | M37: =M$9*N37 -> 16000000 | N37: 80000000 | O37: 300 | P37: 3 | Q37: =Q$9*U37 -> 8000000 | R37: =R$9*U37 -> 32000000 | S37: =S$9*U37 -> 24000000 | T37: =T$9*U37 -> 16000000 | U37: 80000000 | V37: 320 | W37: 2 | X37: =X$9*AB37 -> 8500000 | Y37: =Y$9*AB37 -> 34000000 | Z37: =Z$9*AB37 -> 25500000 | AA37: =AA$9*AB37 -> 17000000 | AB37: 85000000 | AC37: 330 | AD37: 2 | AE37: =SUMIF($J$12:$AB$12,AE$12,$J37:$AB37) -> 24500000 | AF37: =SUMIF($J$12:$AB$12,AF$12,$J37:$AB37) -> 98000000 | AG37: =SUMIF($J$12:$AB$12,AG$12,$J37:$AB37) -> 73500000 | AH37: =SUMIF($J$12:$AB$12,AH$12,$J37:$AB37) -> 49000000 | AI37: =SUMIF($J$12:$AB$12,AI$12,$J37:$AB37) -> 245000000 | AJ37: =SUMIF($J$11:$AD$11,AJ$11,$J37:$AD37) -> 950 | AK37: =SUMIF($J$11:$AD$11,AK$11,$J37:$AD37) -> 7 | AL37: =V37-O37 -> 20 | AM37: =AC37-V37 -> 10 | AN37: =P37-'[14]THÁNG 7'!L35 -> 0
A38: 4 | B38: TDV08 | C38: Trần Thị Anh Thương | D38: Lục Nam, Lục Ngạn, Yên Dũng, Sơn Động, Thành phố | E38: Bắc Giang 2 | F38: =SUMIF('[14]DS đạt từ T1-4'!$D:$D,'Quý 3,2025'!$C38,'[14]DS đạt từ T1-4'!$AI:$AI) -> 0 | G38: =SUMIF('[14]DS đạt từ T1-4'!$D:$D,'Quý 3,2025'!$C38,'[14]DS đạt từ T1-4'!$AN:$AN) -> 0 | H38: =SUMIF([14]T5!D:D,'Quý 3,2025'!C38,[14]T5!AF:AF) -> 11315714 | I38: =SUM(F38:H38)/$I$9 -> 3771904.8 | J38: =J$9*N38 -> 3000000 | K38: =K$9*N38 -> 12000000 | L38: =L$9*N38 -> 9000000 | M38: =M$9*N38 -> 6000000 | N38: 30000000 | O38: 150 | P38: 3 | Q38: =Q$9*U38 -> 3000000 | R38: =R$9*U38 -> 12000000 | S38: =S$9*U38 -> 9000000 | T38: =T$9*U38 -> 6000000 | U38: 30000000 | V38: 180 | W38: 3 | X38: =X$9*AB38 -> 3500000 | Y38: =Y$9*AB38 -> 14000000 | Z38: =Z$9*AB38 -> 10500000 | AA38: =AA$9*AB38 -> 7000000 | AB38: 35000000 | AC38: 200 | AD38: 3 | AE38: =SUMIF($J$12:$AB$12,AE$12,$J38:$AB38) -> 9500000 | AF38: =SUMIF($J$12:$AB$12,AF$12,$J38:$AB38) -> 38000000 | AG38: =SUMIF($J$12:$AB$12,AG$12,$J38:$AB38) -> 28500000 | AH38: =SUMIF($J$12:$AB$12,AH$12,$J38:$AB38) -> 19000000 | AI38: =SUMIF($J$12:$AB$12,AI$12,$J38:$AB38) -> 95000000 | AJ38: =SUMIF($J$11:$AD$11,AJ$11,$J38:$AD38) -> 530 | AK38: =SUMIF($J$11:$AD$11,AK$11,$J38:$AD38) -> 9 | AL38: =V38-O38 -> 30 | AM38: =AC38-V38 -> 20 | AN38: =P38-'[14]THÁNG 7'!L36 -> 0
A39: 5 | B39: TDV09 | C39: Phạm Thị Cúc | D39: Toàn tỉnh | E39: Lạng Sơn | F39: =SUMIF('[14]DS đạt từ T1-4'!$D:$D,'Quý 3,2025'!$C39,'[14]DS đạt từ T1-4'!$AI:$AI) -> 38598143 | G39: =SUMIF('[14]DS đạt từ T1-4'!$D:$D,'Quý 3,2025'!$C39,'[14]DS đạt từ T1-4'!$AN:$AN) -> 1028571.4 | H39: =SUMIF([14]T5!D:D,'Quý 3,2025'!C39,[14]T5!AF:AF) -> 17607429 | I39: =SUM(F39:H39)/$I$9 -> 19078048 | J39: =J$9*N39 -> 3000000 | K39: =K$9*N39 -> 12000000 | L39: =L$9*N39 -> 9000000 | M39: =M$9*N39 -> 6000000 | N39: 30000000 | O39: 150 | P39: 3 | Q39: =Q$9*U39 -> 3000000 | R39: =R$9*U39 -> 12000000 | S39: =S$9*U39 -> 9000000 | T39: =T$9*U39 -> 6000000 | U39: 30000000 | V39: 180 | W39: 3 | X39: =X$9*AB39 -> 3500000 | Y39: =Y$9*AB39 -> 14000000 | Z39: =Z$9*AB39 -> 10500000 | AA39: =AA$9*AB39 -> 7000000 | AB39: 35000000 | AC39: 200 | AD39: 2 | AE39: =SUMIF($J$12:$AB$12,AE$12,$J39:$AB39) -> 9500000 | AF39: =SUMIF($J$12:$AB$12,AF$12,$J39:$AB39) -> 38000000 | AG39: =SUMIF($J$12:$AB$12,AG$12,$J39:$AB39) -> 28500000 | AH39: =SUMIF($J$12:$AB$12,AH$12,$J39:$AB39) -> 19000000 | AI39: =SUMIF($J$12:$AB$12,AI$12,$J39:$AB39) -> 95000000 | AJ39: =SUMIF($J$11:$AD$11,AJ$11,$J39:$AD39) -> 530 | AK39: =SUMIF($J$11:$AD$11,AK$11,$J39:$AD39) -> 8 | AL39: =V39-O39 -> 30 | AM39: =AC39-V39 -> 20 | AN39: =P39-'[14]THÁNG 7'!L37 -> 0
A40: 6 | B40: TDV121 | C40: Lý quốc thắng | D40: Toàn tỉnh | E40: Cao bằng | F40: =SUMIF('[14]DS đạt từ T1-4'!$D:$D,'Quý 3,2025'!$C40,'[14]DS đạt từ T1-4'!$AI:$AI) -> 23716429 | G40: =SUMIF('[14]DS đạt từ T1-4'!$D:$D,'Quý 3,2025'!$C40,'[14]DS đạt từ T1-4'!$AN:$AN) -> 7000000 | H40: =SUMIF([14]T5!D:D,'Quý 3,2025'!C40,[14]T5!AF:AF) -> 33214524 | I40: =SUM(F40:H40)/$I$9 -> 21310317 | J40: =J$9*N40 -> 3000000 | K40: =K$9*N40 -> 12000000 | L40: =L$9*N40 -> 9000000 | M40: =M$9*N40 -> 6000000 | N40: 30000000 | O40: 150 | P40: 3 | Q40: =Q$9*U40 -> 3000000 | R40: =R$9*U40 -> 12000000 | S40: =S$9*U40 -> 9000000 | T40: =T$9*U40 -> 6000000 | U40: 30000000 | V40: 150 | W40: 3 | X40: =X$9*AB40 -> 3500000 | Y40: =Y$9*AB40 -> 14000000 | Z40: =Z$9*AB40 -> 10500000 | AA40: =AA$9*AB40 -> 7000000 | AB40: 35000000 | AC40: 170 | AD40: 2 | AE40: =SUMIF($J$12:$AB$12,AE$12,$J40:$AB40) -> 9500000 | AF40: =SUMIF($J$12:$AB$12,AF$12,$J40:$AB40) -> 38000000 | AG40: =SUMIF($J$12:$AB$12,AG$12,$J40:$AB40) -> 28500000 | AH40: =SUMIF($J$12:$AB$12,AH$12,$J40:$AB40) -> 19000000 | AI40: =SUMIF($J$12:$AB$12,AI$12,$J40:$AB40) -> 95000000 | AJ40: =SUMIF($J$11:$AD$11,AJ$11,$J40:$AD40) -> 470 | AK40: =SUMIF($J$11:$AD$11,AK$11,$J40:$AD40) -> 8 | AL40: =V40-O40 -> 0 | AM40: =AC40-V40 -> 20 | AN40: =P40-'[14]THÁNG 7'!L38 -> 0
A41: 7 | B41: TDV10 | C41: Tuyển TDV mới | D41: Toàn tỉnh | E41: Bắc Cạn | F41: =SUMIF('[14]DS đạt từ T1-4'!$D:$D,'Quý 3,2025'!$C41,'[14]DS đạt từ T1-4'!$AI:$AI) -> 0 | G41: =SUMIF('[14]DS đạt từ T1-4'!$D:$D,'Quý 3,2025'!$C41,'[14]DS đạt từ T1-4'!$AN:$AN) -> 0 | H41: =SUMIF([14]T5!D:D,'Quý 3,2025'!C41,[14]T5!AF:AF) -> 0 | I41: =SUM(F41:H41)/$I$9 -> 0 | J41: =J$9*N41 -> 3000000 | K41: =K$9*N41 -> 12000000 | L41: =L$9*N41 -> 9000000 | M41: =M$9*N41 -> 6000000 | N41: 30000000 | O41: 50 | P41: 3 | Q41: =Q$9*U41 -> 3000000 | R41: =R$9*U41 -> 12000000 | S41: =S$9*U41 -> 9000000 | T41: =T$9*U41 -> 6000000 | U41: 30000000 | V41: 50 | W41: 3 | X41: =X$9*AB41 -> 3500000 | Y41: =Y$9*AB41 -> 14000000 | Z41: =Z$9*AB41 -> 10500000 | AA41: =AA$9*AB41 -> 7000000 | AB41: 35000000 | AC41: 50 | AD41: 3 | AE41: =SUMIF($J$12:$AB$12,AE$12,$J41:$AB41) -> 9500000 | AF41: =SUMIF($J$12:$AB$12,AF$12,$J41:$AB41) -> 38000000 | AG41: =SUMIF($J$12:$AB$12,AG$12,$J41:$AB41) -> 28500000 | AH41: =SUMIF($J$12:$AB$12,AH$12,$J41:$AB41) -> 19000000 | AI41: =SUMIF($J$12:$AB$12,AI$12,$J41:$AB41) -> 95000000 | AJ41: =SUMIF($J$11:$AD$11,AJ$11,$J41:$AD41) -> 150 | AK41: =SUMIF($J$11:$AD$11,AK$11,$J41:$AD41) -> 9 | AL41: =V41-O41 -> 0 | AM41: =AC41-V41 -> 0 | AN41: =P41-'[14]THÁNG 7'!L39 -> 0
...
